<!-- 需求:设置机器人底盘并添加摄像头 -->
<robot name="mycar">
    <!-- 添加一个尺寸极小的link，再去关联初始link与base_link -->
    <link name="base_footptint">
        <!-- 可视化标签 -->
        <visual>
            <!-- 1.形状 -->
            <geometry>
                <!-- 1.1 长方体的长宽高 -->
                <box size="0.001 0.001 0.001" />
            </geometry>
        </visual>
    </link>

    <!-- 1. 底盘link -->
    <link name="base_link">
        <!-- 可视化标签 -->
        <visual>
            <!-- 1.形状 -->
            <geometry>
                <!-- 1.1 长方体的长宽高 -->
                <box size="0.3 0.2 0.1" />
            </geometry>
            <origin xyz="0 0 0" rpy="0 0 0" />
            <material name="car_color">
                <color rgba="0.7 0.5 0 0.8" />
            </material>
        </visual>
    </link>

    <!-- 2. 摄像头link -->
    <link name="camera">
        <!-- 可视化标签 -->
        <visual>
            <!-- 1.形状 -->
            <geometry>
                <!-- 1.1 长方体的长宽高 -->
                <box size="0.02 0.05 0.05" />
            </geometry>
            <!-- 偏移量，先使用默认，后面修改 -->
            <origin xyz="0 0 0.025" rpy="0 0 0" />
            <material name="camera_color">
                <color rgba="0 0 1 0.8" />
            </material>
        </visual>
    </link>

    <!-- 关联base_footprint与base_link -->
    <joint name="link2footprint" type="fixed">
        <!-- 父级link -->
        <parent link="base_footptint"/>
        <!-- 子级link -->
        <child link="base_link" />
        <!-- 需要计算两个 link 的物理中心之间的偏移量 -->
        <origin xyz="0 0 0.05" rpy="0 0 0" />
    </joint>

    <!-- 3. 关节 -->
    <joint name="camera2base" type="continuous">
        <!-- 父级link -->
        <parent link="base_link"/>
        <!-- 子级link -->
        <child link="camera" />
        <!-- 需要计算两个 link 的物理中心之间的偏移量 -->
        <origin xyz="0.12 0 0.05" rpy="0 0 0" />
        <!-- 设置关节旋转参考的坐标轴 -->
        <axis xyz="0 0 1" />
    </joint>
</robot>